Workbook

Sheet README
A1: PARAMANU Reclaimer - Mass & Energy Balance Model (draft v1)
A3: Basis: 1 wet tonne of excavated landfill material. All flows are per tonne.
A4: Five scenarios along the Commercial <-> Nature slider (s = 0 ... 1) are computed side by side.
A6: HOW TO USE
A7: 1. Edit blue cells on a yellow background (Inputs, Composition, Elements, and slider positions on Balance row 4).
A8: 2. Everything else is a formula. Results are on the 'Balance' sheet; charts on 'Charts'.
A9: 3. Check Balance row 30 (mass closure) stays at 0.
A11: SLIDER LOGIC (paper Section 5.2)
A12: Element i is recovered when Value_i + s * Harm_i > Cost_i (Nature mode ADDS harm avoided; it never ignores value)
A13: Cost_i follows the Sherwood relation: Cost = K * c_eff^(-b), where c_eff = feed concentration x pre-sort concentration factor.
A14: Policy overrides: 'Always' (e.g. chlorine captured by off-gas scrubber) and 'Immobilize' (element deliberately left in slag).
A15: Security-sensitive elements and isotopes (nuclear / radiological) are intentionally NOT listed - see paper Section 8.
... A27: Blue on yellow = input you can change. Black = formula. Grey rows = totals.

Sheet Balance
A1: PARAMANU Reclaimer - mass & energy balance per wet tonne
A2: Columns = positions on the Commercial <-> Nature slider. Edit slider values in row 4.
A4: Slider position s | B4: Unit | C4: 0 | D4: 0.25 | E4: 0.5 | F4: 0.75 | G4: 1
C5: Commercial | E5: Balanced | G5: Nature
A7: SLIDER-DEPENDENT SETTINGS
A8: Fines vitrified fraction | B8: fraction | C8: =Inputs!$B$34+C$4*(Inputs!$C$34-Inputs!$B$34) | D8: =Inputs!$B$34+D$4*(Inputs!$C$34-Inputs!$B$34) | E8: =Inputs!$B$34+E$4*(Inputs!$C$34-Inputs!$B$34) | F8: =Inputs!$B$34+F$4*(Inputs!$C$34-Inputs!$B$34) | G8: =Inputs!$B$34+G$4*(Inputs!$C$34-Inputs!$B$34)
A9: Hydromet + water treatment intensity | B9: kWh/t | C9: =Inputs!$B$35+C$4*(Inputs!$C$35-Inputs!$B$35) | D9: =Inputs!$B$35+D$4*(Inputs!$C$35-Inputs!$B$35) | E9: =Inputs!$B$35+E$4*(Inputs!$C$35-Inputs!$B$35) | F9: =Inputs!$B$35+F$4*(Inputs!$C$35-Inputs!$B$35) | G9: =Inputs!$B$35+G$4*(Inputs!$C$35-Inputs!$B$35)
A10: PFAS / toxin destruction intensity | B10: kWh/t | C10: =Inputs!$B$36+C$4*(Inputs!$C$36-Inputs!$B$36) | D10: =Inputs!$B$36+D$4*(Inputs!$C$36-Inputs!$B$36) | E10: =Inputs!$B$36+E$4*(Inputs!$C$36-Inputs!$B$36) | F10: =Inputs!$B$36+F$4*(Inputs!$C$36-Inputs!$B$36) | G10: =Inputs!$B$36+G$4*(Inputs!$C$36-Inputs!$B$36)
A11: Electrokinetic treatment intensity | B11: kWh/t | C11: =Inputs!$B$37+C$4*(Inputs!$C$37-Inputs!$B$37) | D11: =Inputs!$B$37+D$4*(Inputs!$C$37-Inputs!$B$37) | E11: =Inputs!$B$37+E$4*(Inputs!$C$37-Inputs!$B$37) | F11: =Inputs!$B$37+F$4*(Inputs!$C$37-Inputs!$B$37) | G11: =Inputs!$B$37+G$4*(Inputs!$C$37-Inputs!$B$37)
A12: Renewable share of purchased electricity | B12: fraction | C12: =Inputs!$B$38+C$4*(Inputs!$C$38-Inputs!$B$38) | D12: =Inputs!$B$38+D$4*(Inputs!$C$38-Inputs!$B$38) | E12: =Inputs!$B$38+E$4*(Inputs!$C$38-Inputs!$B$38) | F12: =Inputs!$B$38+F$4*(Inputs!$C$38-Inputs!$B$38) | G12: =Inputs!$B$38+G$4*(Inputs!$C$38-Inputs!$B$38)
A14: MASS BALANCE
A15: Inputs
A16: Wet feed | B16: kg | C16: =Inputs!$B$4 | D16: =Inputs!$B$4 | E16: =Inputs!$B$4 | F16: =Inputs!$B$4 | G16: =Inputs!$B$4
A17: memo: moisture | B17: kg | C17: =Inputs!$B$4*Inputs!$B$5 | D17: =Inputs!$B$4*Inputs!$B$5 | E17: =Inputs!$B$4*Inputs!$B$5 | F17: =Inputs!$B$4*Inputs!$B$5 | G17: =Inputs!$B$4*Inputs!$B$5
A18: memo: dry solids | B18: kg | C18: =Composition!$C$13 | D18: =Composition!$C$13 | E18: =Composition!$C$13 | F18: =Composition!$C$13 | G18: =Composition!$C$13
A19: Oxidant (O2 / steam) to gasifier | B19: kg | C19: =Composition!$I$13*Inputs!$B$6 | D19: =Composition!$I$13*Inputs!$B$6 | E19: =Composition!$I$13*Inputs!$B$6 | F19: =Composition!$I$13*Inputs!$B$6 | G19: =Composition!$I$13*Inputs!$B$6
A20: Reagents bound into stable compounds | B20: kg | C20: =Elements!T27-Elements!T26 | D20: =Elements!U27-Elements!U26 | E20: =Elements!V27-Elements!V26 | F20: =Elements!W27-Elements!W26 | G20: =Elements!X27-Elements!X26
A21: TOTAL IN | B21: kg | C21: =C16+C19+C20 | D21: =D16+D19+D20 | E21: =E16+E19+E20 | F21: =F16+F19+F20 | G21: =G16+G19+G20
A22: Outputs
A23: Water vapour -> condensed & treated | B23: kg | C23: =C17 | D23: =D17 | E23: =E17 | F23: =F17 | G23: =G17
A24: Syngas (organics + oxidant) | B24: kg | C24: =Composition!$I$13+C19 | D24: =Composition!$I$13+D19 | E24: =Composition!$I$13+E19 | F24: =Composition!$I$13+F19 | G24: =Composition!$I$13+G19
A25: Clean fines -> reused as cover soil | B25: kg | C25: =Composition!$C$4*(1-C8) | D25: =Composition!$C$4*(1-D8) | E25: =Composition!$C$4*(1-E8) | F25: =Composition!$C$4*(1-F8) | G25: =Composition!$C$4*(1-G8)
A26: Aggregate (washed glass / stone) | B26: kg | C26: =Composition!$C$7*Inputs!$B$16 | D26: =Composition!$C$7*Inputs!$B$16 | E26: =Composition!$C$7*Inputs!$B$16 | F26: =Composition!$C$7*Inputs!$B$16 | G26: =Composition!$C$7*Inputs!$B$16
A27: Recovered products (metals + stable compounds) | B27: kg | C27: =Elements!T27 | D27: =Elements!U27 | E27: =Elements!V27 | F27: =Elements!W27 | G27: =Elements!X27
A28: Vitrified slag (balancing item) | B28: kg | C28: =C18-Composition!$I$13-C25-C26-Elements!T26 | D28: =D18-Composition!$I$13-D25-D26-Elements!U26 | E28: =E18-Composition!$I$13-E25-E26-Elements!V26 | F28: =F18-Composition!$I$13-F25-F26-Elements!W26 | G28: =G18-Composition!$I$13-G25-G26-Elements!X26
A29: TOTAL OUT | B29: kg | C29: =C23+C24+C25+C26+C27+C28 | D29: =D23+D24+D25+D26+D27+D28 | E29: =E23+E24+E25+E26+E27+E28 | F29: =F23+F24+F25+F26+F27+F28 | G29: =G23+G24+G25+G26+G27+G28
A30: Closure check (out - in), must be 0 | B30: kg | C30: =ROUND(C29-C21,6) | D30: =ROUND(D29-D21,6) | E30: =ROUND(E29-E21,6) | F30: =ROUND(F29-F21,6) | G30: =ROUND(G29-G21,6)
A32: Recovered elements (elemental mass) | B32: kg | C32: =Elements!T26 | D32: =Elements!U26 | E32: =Elements!V26 | F32: =Elements!W26 | G32: =Elements!X26
A33: Number of elements recovered | B33: count | C33: =Elements!O26 | D33: =Elements!P26 | E33: =Elements!Q26 | F33: =Elements!R26 | G33: =Elements!S26
A34: Slag as share of dry solids | B34: % | C34: =C28/C18 | D34: =D28/D18 | E34: =E28/E18 | F34: =F28/F18 | G34: =G28/G18
A36: HYDROGEN & WATER
A37: Syngas chemical energy | B37: kWh | C37: =Composition!$J$13*Inputs!$B$9 | D37: =Composition!$J$13*Inputs!$B$9 | E37: =Composition!$J$13*Inputs!$B$9 | F37: =Composition!$J$13*Inputs!$B$9 | G37: =Composition!$J$13*Inputs!$B$9
A38: Hydrogen in syngas | B38: kg | C38: =C37*Inputs!$B$11/Inputs!$B$12 | D38: =D37*Inputs!$B$11/Inputs!$B$12 | E38: =E37*Inputs!$B$11/Inputs!$B$12 | F38: =F37*Inputs!$B$11/Inputs!$B$12 | G38: =G37*Inputs!$B$11/Inputs!$B$12
A39: Water formed when that H2 is used (x9) | B39: kg | C39: =C38*9 | D39: =D38*9 | E39: =E38*9 | F39: =F38*9 | G39: =G38*9
A40: Process water make-up | B40: kg | C40: =Inputs!$B$17 | D40: =Inputs!$B$17 | E40: =Inputs!$B$17 | F40: =Inputs!$B$17 | G40: =Inputs!$B$17
A41: Water to treatment, then discharge (NPDES) | B41: kg | C41: =C23+C39+C40 | D41: =D23+D39+D40 | E41: =E23+E39+E40 | F41: =F23+F39+F40 | G41: =G23+G39+G40
A43: ELECTRICITY BALANCE
A44: Demand
A45: Excavation & handling | B45: kWh | C45: =Inputs!$B$20*Inputs!$B$4/1000 | D45: =Inputs!$B$20*Inputs!$B$4/1000 | E45: =Inputs!$B$20*Inputs!$B$4/1000 | F45: =Inputs!$B$20*Inputs!$B$4/1000 | G45: =Inputs!$B$20*Inputs!$B$4/1000
A46: Pre-sort | B46: kWh | C46: =Inputs!$B$21*Inputs!$B$4/1000 | D46: =Inputs!$B$21*Inputs!$B$4/1000 | E46: =Inputs!$B$21*Inputs!$B$4/1000 | F46: =Inputs!$B$21*Inputs!$B$4/1000 | G46: =Inputs!$B$21*Inputs!$B$4/1000
...

Sheet Charts
A1: Slider scenarios (x-axis = slider position, 0 = Commercial, 1 = Nature)

Sheet Inputs
A1: Inputs & assumptions
A2: Parameter | B2: Value | C2: Unit | D2: Note / source
A3: GENERAL
A4: Feed basis (wet) | B4: 1000 | C4: kg | D4: 1 wet tonne
A5: Moisture fraction of feed | B5: 0.25 | C5: fraction | D5: Old landfill material, typical 15-35%
A6: Oxidant (O2/steam) per kg organic | B6: 0.4 | C6: kg/kg | D6: Lumped into syngas mass
A7: Sherwood constant K | B7: 0.01 | C7: $/kg at c = 1 | D7: Calibrate to known recovery costs
A8: Sherwood exponent b | B8: 0.9 | C8: - | D8: Literature ~0.8-1.0
A9: Cold gas efficiency (gasifier) | B9: 0.7 | C9: fraction | D9: Chemical energy in syngas / in feed
A10: Syngas -> electricity efficiency | B10: 0.4 | C10: fraction | D10: Gas engine ~35%, fuel cell ~50%
A11: H2 share of syngas energy | B11: 0.45 | C11: fraction | D11: Depends on steam, water-gas shift
A12: H2 lower heating value | B12: 33.3 | C12: kWh/kg | D12: Physical constant
A13: Waste-heat recovery fraction | B13: 0.5 | C13: fraction | D13: Of non-electric syngas energy
A14: Latent heat of water | B14: 2.26 | C14: MJ/kg | D14: Physical constant
A15: Dryer efficiency | B15: 0.8 | C15: fraction
A16: Aggregate recovery from glass/stone | B16: 0.9 | C16: fraction | D16: Rest to slag
A17: Process water make-up | B17: 500 | C17: kg/t | D17: Washing, leaching, scrubbing
A19: FIXED ENERGY INTENSITIES
A20: Excavation & handling | B20: 15 | C20: kWh/t wet | D20: Diesel equivalent
A21: Pre-sort (shred, screen, sensors, magnets) | B21: 30 | C21: kWh/t wet
A22: Plasma torch electricity | B22: 0.4 | C22: kWh/kg combustible | D22: Highly vendor-dependent
A23: Vitrification (melting slag) | B23: 0.6 | C23: kWh/kg slag | D23: Glass melting ~0.4-0.8
A24: Off-gas cleaning | B24: 20 | C24: kWh/t wet | D24: Fans, scrubbers, carbon beds
A26: ECONOMICS
A27: Tipping fee received | B27: 60 | C27: $/t wet | D27: Paid by city/county
A28: Base processing cost (labor, capex, O&M) | B28: 90 | C28: $/t wet
A29: Electricity purchase price | B29: 0.1 | C29: $/kWh
A30: Electricity export price | B30: 0.05 | C30: $/kWh
A31: Soil / aggregate / slag sale price | B31: 0.005 | C31: $/kg | D31: $5 per tonne
A33: SLIDER-DEPENDENT PARAMETERS | B33: Commercial (s=0) | C33: Nature (s=1) | D33: Unit | E33: Note
A34: Fines vitrified (rest reused as cover soil) | B34: 0.1 | C34: 0.8 | D34: fraction | E34: Nature: treat contaminated fines
A35: Hydrometallurgy + water treatment | B35: 30 | C35: 80 | D35: kWh/t wet
A36: PFAS / organic toxin destruction | B36: 0 | C36: 40 | D36: kWh/t wet | E36: Cold plasma or supercritical water
A37: Electrokinetic treatment of fines | B37: 0 | C37: 30 | D37: kWh/t wet
A38: Renewable share of purchased electricity | B38: 0.3 | C38: 1 | D38: fraction | E38: Nature end = 100% renewable

Sheet Composition
A1: Feedstock composition (dry basis)
A3: Component | B3: Dry fraction | C3: Dry mass (kg/t) | D3: LHV (MJ/kg dry) | E3: Ash fraction | F3: Combustible (1/0) | G3: Route | H3: Note | I3: Organic to syngas (kg) | J3: Chemical energy (kWh) | K3: Combustible mass (kg)
A4: Fines / soil | B4: 0.5 | C4: =B4*Inputs!$B$4*(1-Inputs!$B$5) | D4: 0 | E4: 0 | F4: 0 | G4: Screen -> reuse as cover soil or vitrify | H4: ELFM studies: 40-60% | I4: =C4*F4*(1-E4) | J4: =C4*F4*D4/3.6 | K4: =C4*F4
A5: Plastics | B5: 0.18 | C5: =B5*Inputs!$B$4*(1-Inputs!$B$5) | D5: 35 | E5: 0.05 | F5: 1 | G5: Plasma gasification -> syngas | I5: =C5*F5*(1-E5) | J5: =C5*F5*D5/3.6 | K5: =C5*F5
A6: Paper / wood / textiles | B6: 0.12 | C6: =B6*Inputs!$B$4*(1-Inputs!$B$5) | D6: 15 | E6: 0.1 | F6: 1 | G6: Plasma gasification -> syngas | H6: Mostly degraded in old cells | I6: =C6*F6*(1-E6) | J6: =C6*F6*D6/3.6 | K6: =C6*F6
A7: Glass / stone / ceramics | B7: 0.12 | C7: =B7*Inputs!$B$4*(1-Inputs!$B$5) | D7: 0 | E7: 0 | F7: 0 | G7: Wash -> aggregate | I7: =C7*F7*(1-E7) | J7: =C7*F7*D7/3.6 | K7: =C7*F7
A8: Ferrous metals | B8: 0.04 | C8: =B8*Inputs!$B$4*(1-Inputs!$B$5) | D8: 0 | E8: 0 | F8: 0 | G8: Magnet -> smelt | I8: =C8*F8*(1-E8) | J8: =C8*F8*D8/3.6 | K8: =C8*F8
A9: Non-ferrous metals | B9: 0.012 | C9: =B9*Inputs!$B$4*(1-Inputs!$B$5) | D9: 0 | E9: 0 | F9: 0 | G9: Eddy current -> smelt/refine | I9: =C9*F9*(1-E9) | J9: =C9*F9*D9/3.6 | K9: =C9*F9
A10: E-waste | B10: 0.003 | C10: =B10*Inputs!$B$4*(1-Inputs!$B$5) | D10: 0 | E10: 0 | F10: 0 | G10: Sensor sort -> precious metal refining | H10: Main gold/silver/Pd source | I10: =C10*F10*(1-E10) | J10: =C10*F10*D10/3.6 | K10: =C10*F10
A11: Batteries | B11: 0.0005 | C11: =B11*Inputs!$B$4*(1-Inputs!$B$5) | D11: 0 | E11: 0 | F11: 0 | G11: Sensor sort -> hydrometallurgy | H11: Li, Co, Ni, Cd | I11: =C11*F11*(1-E11) | J11: =C11*F11*D11/3.6 | K11: =C11*F11
A12: Other / hazardous | B12: 0.0245 | C12: =B12*Inputs!$B$4*(1-Inputs!$B$5) | D12: 0 | E12: 0 | F12: 0 | G12: Mixed; to slag after treatment | H12: Balancing fraction | I12: =C12*F12*(1-E12) | J12: =C12*F12*D12/3.6 | K12: =C12*F12
A13: TOTAL | B13: =SUM(B4:B12) | C13: =SUM(C4:C12) | I13: =SUM(I4:I12) | J13: =SUM(J4:J12) | K13: =SUM(K4:K12)
A14: Check: dry fractions must sum to 100% | B14: =IF(ABS(B13-1)<0.0001,"OK","FIX")

Sheet Elements
A1: Element inventory, value, harm, Sherwood cost and slider recovery decisions
A2: Concentrations are placeholder estimates of the RECOVERABLE form in dry feed. Pre-sort factor = how much sorting concentrates the element before extraction.
A4: Element | B4: Symbol | C4: Conc. in dry feed (ppm) | D4: Pre-sort conc. factor | E4: Effective conc. (fraction) | F4: Value ($/kg) | G4: Harm if left ($/kg) | H4: Recovery efficiency | I4: Refining energy (kWh/kg) | J4: Policy | K4: Product form | L4: Product / element mass ratio | M4: Sherwood cost ($/kg) | N4: Mass in feed (kg/t) | O4: Recover? s1 | P4: Recover? s2 | Q4: Recover? s3 | R4: Recover? s4 | S4: Recover? s5 | T4: Recovered kg s1 | U4: Recovered kg s2 | V4: Recovered kg s3 | W4: Recovered kg s4 | X4: Recovered kg s5
A5: Iron | B5: Fe | C5: 35000 | D5: 20 | E5: =MIN(1,C5*D5/1000000) | F5: 0.3 | G5: 0 | H5: 0.9 | I5: 0.6 | J5: Auto | K5: Steel scrap / pig iron | L5: 1 | M5: =Inputs!$B$7*E5^(-Inputs!$B$8) | N5: =C5/1000000*Composition!$C$13 | O5: =IF($J5="Always",1,IF($J5="Immobilize",0,IF($F5+Balance!C$4*$G5>$M5,1,0))) | P5: =IF($J5="Always",1,IF($J5="Immobilize",0,IF($F5+Balance!D$4*$G5>$M5,1,0))) | Q5: =IF($J5="Always",1,IF($J5="Immobilize",0,IF($F5+Balance!E$4*$G5>$M5,1,0))) | R5: =IF($J5="Always",1,IF($J5="Immobilize",0,IF($F5+Balance!F$4*$G5>$M5,1,0))) | S5: =IF($J5="Always",1,IF($J5="Immobilize",0,IF($F5+Balance!G$4*$G5>$M5,1,0))) | T5: =$N5*$H5*O5 | U5: =$N5*$H5*P5 | V5: =$N5*$H5*Q5 | W5: =$N5*$H5*R5 | X5: =$N5*$H5*S5
A6: Aluminium | B6: Al | C6: 6000 | D6: 50 | E6: =MIN(1,C6*D6/1000000) | F6: 1.5 | G6: 0 | H6: 0.8 | I6: 1 | J6: Auto | K6: Al ingot | L6: 1 | M6: =Inputs!$B$7*E6^(-Inputs!$B$8) | N6: =C6/1000000*Composition!$C$13 | O6: =IF($J6="Always",1,IF($J6="Immobilize",0,IF($F6+Balance!C$4*$G6>$M6,1,0))) | P6: =IF($J6="Always",1,IF($J6="Immobilize",0,IF($F6+Balance!D$4*$G6>$M6,1,0))) | Q6: =IF($J6="Always",1,IF($J6="Immobilize",0,IF($F6+Balance!E$4*$G6>$M6,1,0))) | R6: =IF($J6="Always",1,IF($J6="Immobilize",0,IF($F6+Balance!F$4*$G6>$M6,1,0))) | S6: =IF($J6="Always",1,IF($J6="Immobilize",0,IF($F6+Balance!G$4*$G6>$M6,1,0))) | T6: =$N6*$H6*O6 | U6: =$N6*$H6*P6 | V6: =$N6*$H6*Q6 | W6: =$N6*$H6*R6 | X6: =$N6*$H6*S6
A7: Copper | B7: Cu | C7: 2500 | D7: 30 | E7: =MIN(1,C7*D7/1000000) | F7: 9 | G7: 5 | H7: 0.85 | I7: 1.5 | J7: Auto | K7: Cathode copper | L7: 1 | M7: =Inputs!$B$7*E7^(-Inputs!$B$8) | N7: =C7/1000000*Composition!$C$13 | O7: =IF($J7="Always",1,IF($J7="Immobilize",0,IF($F7+Balance!C$4*$G7>$M7,1,0))) | P7: =IF($J7="Always",1,IF($J7="Immobilize",0,IF($F7+Balance!D$4*$G7>$M7,1,0))) | Q7: =IF($J7="Always",1,IF($J7="Immobilize",0,IF($F7+Balance!E$4*$G7>$M7,1,0))) | R7: =IF($J7="Always",1,IF($J7="Immobilize",0,IF($F7+Balance!F$4*$G7>$M7,1,0))) | S7: =IF($J7="Always",1,IF($J7="Immobilize",0,IF($F7+Balance!G$4*$G7>$M7,1,0))) | T7: =$N7*$H7*O7 | U7: =$N7*$H7*P7 | V7: =$N7*$H7*Q7 | W7: =$N7*$H7*R7 | X7: =$N7*$H7*S7
A8: Zinc | B8: Zn | C8: 1500 | D8: 5 | E8: =MIN(1,C8*D8/1000000) | F8: 2.7 | G8: 10 | H8: 0.7 | I8: 3 | J8: Auto | K8: Zn oxide / metal | L8: 1 | M8: =Inputs!$B$7*E8^(-Inputs!$B$8) | N8: =C8/1000000*Composition!$C$13 | O8: =IF($J8="Always",1,IF($J8="Immobilize",0,IF($F8+Balance!C$4*$G8>$M8,1,0))) | P8: =IF($J8="Always",1,IF($J8="Immobilize",0,IF($F8+Balance!D$4*$G8>$M8,1,0))) | Q8: =IF($J8="Always",1,IF($J8="Immobilize",0,IF($F8+Balance!E$4*$G8>$M8,1,0))) | R8: =IF($J8="Always",1,IF($J8="Immobilize",0,IF($F8+Balance!F$4*$G8>$M8,1,0))) | S8: =IF($J8="Always",1,IF($J8="Immobilize",0,IF($F8+Balance!G$4*$G8>$M8,1,0))) | T8: =$N8*$H8*O8 | U8: =$N8*$H8*P8 | V8: =$N8*$H8*Q8 | W8: =$N8*$H8*R8 | X8: =$N8*$H8*S8
A9: Lead | B9: Pb | C9: 800 | D9: 10 | E9: =MIN(1,C9*D9/1000000) | F9: 2 | G9: 200 | H9: 0.75 | I9: 1 | J9: Auto | K9: Lead bullion | L9: 1 | M9: =Inputs!$B$7*E9^(-Inputs!$B$8) | N9: =C9/1000000*Composition!$C$13 | O9: =IF($J9="Always",1,IF($J9="Immobilize",0,IF($F9+Balance!C$4*$G9>$M9,1,0))) | P9: =IF($J9="Always",1,IF($J9="Immobilize",0,IF($F9+Balance!D$4*$G9>$M9,1,0))) | Q9: =IF($J9="Always",1,IF($J9="Immobilize",0,IF($F9+Balance!E$4*$G9>$M9,1,0))) | R9: =IF($J9="Always",1,IF($J9="Immobilize",0,IF($F9+Balance!F$4*$G9>$M9,1,0))) | S9: =IF($J9="Always",1,IF($J9="Immobilize",0,IF($F9+Balance!G$4*$G9>$M9,1,0))) | T9: =$N9*$H9*O9 | U9: =$N9*$H9*P9 | V9: =$N9*$H9*Q9 | W9: =$N9*$H9*R9 | X9: =$N9*$H9*S9
A10: Nickel | B10: Ni | C10: 300 | D10: 20 | E10: =MIN(1,C10*D10/1000000) | F10: 16 | G10: 20 | H10: 0.6 | I10: 4 | J10: Auto | K10: Ni metal / sulfate | L10: 1 | M10: =Inputs!$B$7*E10^(-Inputs!$B$8) | N10: =C10/1000000*Composition!$C$13 | O10: =IF($J10="Always",1,IF($J10="Immobilize",0,IF($F10+Balance!C$4*$G10>$M10,1,0))) | P10: =IF($J10="Always",1,IF($J10="Immobilize",0,IF($F10+Balance!D$4*$G10>$M10,1,0))) | Q10: =IF($J10="Always",1,IF($J10="Immobilize",0,IF($F10+Balance!E$4*$G10>$M10,1,0))) | R10: =IF($J10="Always",1,IF($J10="Immobilize",0,IF($F10+Balance!F$4*$G10>$M10,1,0))) | S10: =IF($J10="Always",1,IF($J10="Immobilize",0,IF($F10+Balance!G$4*$G10>$M10,1,0))) | T10: =$N10*$H10*O10 | U10: =$N10*$H10*P10 | V10: =$N10*$H10*Q10 | W10: =$N10*$H10*R10 | X10: =$N10*$H10*S10
A11: Tin | B11: Sn | C11: 200 | D11: 20 | E11: =MIN(1,C11*D11/1000000) | F11: 30 | G11: 1 | H11: 0.6 | I11: 3 | J11: Auto | K11: Tin metal | L11: 1 | M11: =Inputs!$B$7*E11^(-Inputs!$B$8) | N11: =C11/1000000*Composition!$C$13 | O11: =IF($J11="Always",1,IF($J11="Immobilize",0,IF($F11+Balance!C$4*$G11>$M11,1,0))) | P11: =IF($J11="Always",1,IF($J11="Immobilize",0,IF($F11+Balance!D$4*$G11>$M11,1,0))) | Q11: =IF($J11="Always",1,IF($J11="Immobilize",0,IF($F11+Balance!E$4*$G11>$M11,1,0))) | R11: =IF($J11="Always",1,IF($J11="Immobilize",0,IF($F11+Balance!F$4*$G11>$M11,1,0))) | S11: =IF($J11="Always",1,IF($J11="Immobilize",0,IF($F11+Balance!G$4*$G11>$M11,1,0))) | T11: =$N11*$H11*O11 | U11: =$N11*$H11*P11 | V11: =$N11*$H11*Q11 | W11: =$N11*$H11*R11 | X11: =$N11*$H11*S11
A12: Antimony | B12: Sb | C12: 30 | D12: 5 | E12: =MIN(1,C12*D12/1000000) | F12: 40 | G12: 50 | H12: 0.5 | I12: 5 | J12: Auto | K12: Sb2O3 | L12: 1.2 | M12: =Inputs!$B$7*E12^(-Inputs!$B$8) | N12: =C12/1000000*Composition!$C$13 | O12: =IF($J12="Always",1,IF($J12="Immobilize",0,IF($F12+Balance!C$4*$G12>$M12,1,0))) | P12: =IF($J12="Always",1,IF($J12="Immobilize",0,IF($F12+Balance!D$4*$G12>$M12,1,0))) | Q12: =IF($J12="Always",1,IF($J12="Immobilize",0,IF($F12+Balance!E$4*$G12>$M12,1,0))) | R12: =IF($J12="Always",1,IF($J12="Immobilize",0,IF($F12+Balance!F$4*$G12>$M12,1,0))) | S12: =IF($J12="Always",1,IF($J12="Immobilize",0,IF($F12+Balance!G$4*$G12>$M12,1,0))) | T12: =$N12*$H12*O12 | U12: =$N12*$H12*P12 | V12: =$N12*$H12*Q12 | W12: =$N12*$H12*R12 | X12: =$N12*$H12*S12
A13: Chromium | B13: Cr | C13: 100 | D13: 2 | E13: =MIN(1,C13*D13/1000000) | F13: 10 | G13: 500 | H13: 0.5 | I13: 5 | J13: Auto | K13: Cr2O3 (stable Cr III) | L13: 1.46 | M13: =Inputs!$B$7*E13^(-Inputs!$B$8) | N13: =C13/1000000*Composition!$C$13 | O13: =IF($J13="Always",1,IF($J13="Immobilize",0,IF($F13+Balance!C$4*$G13>$M13,1,0))) | P13: =IF($J13="Always",1,IF($J13="Immobilize",0,IF($F13+Balance!D$4*$G13>$M13,1,0))) | Q13: =IF($J13="Always",1,IF($J13="Immobilize",0,IF($F13+Balance!E$4*$G13>$M13,1,0))) | R13: =IF($J13="Always",1,IF($J13="Immobilize",0,IF($F13+Balance!F$4*$G13>$M13,1,0))) | S13: =IF($J13="Always",1,IF($J13="Immobilize",0,IF($F13+Balance!G$4*$G13>$M13,1,0))) | T13: =$N13*$H13*O13 | U13: =$N13*$H13*P13 | V13: =$N13*$H13*Q13 | W13: =$N13*$H13*R13 | X13: =$N13*$H13*S13
A14: Cobalt | B14: Co | C14: 15 | D14: 300 | E14: =MIN(1,C14*D14/1000000) | F14: 30 | G14: 50 | H14: 0.6 | I14: 10 | J14: Auto | K14: Co metal / hydroxide | L14: 1 | M14: =Inputs!$B$7*E14^(-Inputs!$B$8) | N14: =C14/1000000*Composition!$C$13 | O14: =IF($J14="Always",1,IF($J14="Immobilize",0,IF($F14+Balance!C$4*$G14>$M14,1,0))) | P14: =IF($J14="Always",1,IF($J14="Immobilize",0,IF($F14+Balance!D$4*$G14>$M14,1,0))) | Q14: =IF($J14="Always",1,IF($J14="Immobilize",0,IF($F14+Balance!E$4*$G14>$M14,1,0))) | R14: =IF($J14="Always",1,IF($J14="Immobilize",0,IF($F14+Balance!F$4*$G14>$M14,1,0))) | S14: =IF($J14="Always",1,IF($J14="Immobilize",0,IF($F14+Balance!G$4*$G14>$M14,1,0))) | T14: =$N14*$H14*O14 | U14: =$N14*$H14*P14 | V14: =$N14*$H14*Q14 | W14: =$N14*$H14*R14 | X14: =$N14*$H14*S14
A15: Lithium | B15: Li | C15: 20 | D15: 500 | E15: =MIN(1,C15*D15/1000000) | F15: 60 | G15: 5 | H15: 0.5 | I15: 30 | J15: Auto | K15: Li2CO3 | L15: 5.32 | M15: =Inputs!$B$7*E15^(-Inputs!$B$8) | N15: =C15/1000000*Composition!$C$13 | O15: =IF($J15="Always",1,IF($J15="Immobilize",0,IF($F15+Balance!C$4*$G15>$M15,1,0))) | P15: =IF($J15="Always",1,IF($J15="Immobilize",0,IF($F15+Balance!D$4*$G15>$M15,1,0))) | Q15: =IF($J15="Always",1,IF($J15="Immobilize",0,IF($F15+Balance!E$4*$G15>$M15,1,0))) | R15: =IF($J15="Always",1,IF($J15="Immobilize",0,IF($F15+Balance!F$4*$G15>$M15,1,0))) | S15: =IF($J15="Always",1,IF($J15="Immobilize",0,IF($F15+Balance!G$4*$G15>$M15,1,0))) | T15: =$N15*$H15*O15 | U15: =$N15*$H15*P15 | V15: =$N15*$H15*Q15 | W15: =$N15*$H15*R15 | X15: =$N15*$H15*S15
A16: Rare earths (total) | B16: REE | C16: 30 | D16: 200 | E16: =MIN(1,C16*D16/1000000) | F16: 50 | G16: 1 | H16: 0.4 | I16: 50 | J16: Auto | K16: Mixed RE oxides | L16: 1.17 | M16: =Inputs!$B$7*E16^(-Inputs!$B$8) | N16: =C16/1000000*Composition!$C$13 | O16: =IF($J16="Always",1,IF($J16="Immobilize",0,IF($F16+Balance!C$4*$G16>$M16,1,0))) | P16: =IF($J16="Always",1,IF($J16="Immobilize",0,IF($F16+Balance!D$4*$G16>$M16,1,0))) | Q16: =IF($J16="Always",1,IF($J16="Immobilize",0,IF($F16+Balance!E$4*$G16>$M16,1,0))) | R16: =IF($J16="Always",1,IF($J16="Immobilize",0,IF($F16+Balance!F$4*$G16>$M16,1,0))) | S16: =IF($J16="Always",1,IF($J16="Immobilize",0,IF($F16+Balance!G$4*$G16>$M16,1,0))) | T16: =$N16*$H16*O16 | U16: =$N16*$H16*P16 | V16: =$N16*$H16*Q16 | W16: =$N16*$H16*R16 | X16: =$N16*$H16*S16
... A24: Chlorine | B24: Cl | C24: 5000 | D24: 1 | E24: =MIN(1,C24*D24/1000000) | F24: 0.05 | G24: 1 | H24: 0.9 | I24: 0.5 | J24: Always | K24: NaCl (off-gas scrubber) | L24: 1.65 | M24: =Inputs!$B$7*E24^(-Inputs!$B$8) | N24: =C24/1000000*Composition!$C$13 | O24: =IF($J24="Always",1,IF($J24="Immobilize",0,IF($F24+Balance!C$4*$G24>$M24,1,0))) | P24: =IF($J24="Always",1,IF($J24="Immobilize",0,IF($F24+Balance!D$4*$G24>$M24,1,0))) | Q24: =IF($J24="Always",1,IF($J24="Immobilize",0,IF($F24+Balance!E$4*$G24>$M24,1,0))) | R24: =IF($J24="Always",1,IF($J24="Immobilize",0,IF($F24+Balance!F$4*$G24>$M24,1,0))) | S24: =IF($J24="Always",1,IF($J24="Immobilize",0,IF($F24+Balance!G$4*$G24>$M24,1,0))) | T24: =$N24*$H24*O24 | U24: =$N24*$H24*P24 | V24: =$N24*$H24*Q24 | W24: =$N24*$H24*R24 | X24: =$N24*$H24*S24
A26: Recovered elements (kg, elemental) | N26: Count recovered: | O26: =SUM(O5:O24) | P26: =SUM(P5:P24) | Q26: =SUM(Q5:Q24) | R26: =SUM(R5:R24) | S26: =SUM(S5:S24) | T26: =SUM(T5:T24) | U26: =SUM(U5:U24) | V26: =SUM(V5:V24) | ... X26: =SUM(X5:X24)
A27: Recovered products (kg, sold form) | T27: =SUMPRODUCT(T5:T24,$L$5:$L$24) | U27: =SUMPRODUCT(U5:U24,$L$5:$L$24) | V27: =SUMPRODUCT(V5:V24,$L$5:$L$24) | W27: =SUMPRODUCT(W5:W24,$L$5:$L$24) | X27: =SUMPRODUCT(X5:X24,$L$5:$L$24)
A28: Product revenue ($) | T28: =SUMPRODUCT(T5:T24,$F$5:$F$24) | U28: =SUMPRODUCT(U5:U24,$F$5:$F$24) | V28: =SUMPRODUCT(V5:V24,$F$5:$F$24) | W28: =SUMPRODUCT(W5:W24,$F$5:$F$24) | X28: =SUMPRODUCT(X5:X24,$F$5:$F$24)
A29: Recovery cost - Sherwood ($) | T29: =SUMPRODUCT(T5:T24,$M$5:$M$24) | U29: =SUMPRODUCT(U5:U24,$M$5:$M$24) | V29: =SUMPRODUCT(V5:V24,$M$5:$M$24) | W29: =SUMPRODUCT(W5:W24,$M$5:$M$24) | X29: =SUMPRODUCT(X5:X24,$M$5:$M$24)
A30: Environmental harm avoided ($) | T30: =SUMPRODUCT(T5:T24,$G$5:$G$24) | U30: =SUMPRODUCT(U5:U24,$G$5:$G$24) | V30: =SUMPRODUCT(V5:V24,$G$5:$G$24) | W30: =SUMPRODUCT(W5:W24,$G$5:$G$24) | X30: =SUMPRODUCT(X5:X24,$G$5:$G$24)
A31: Refining energy (kWh) | T31: =SUMPRODUCT(T5:T24,$I$5:$I$24) | U31: =SUMPRODUCT(U5:U24,$I$5:$I$24) | V31: =SUMPRODUCT(V5:V24,$I$5:$I$24) | W31: =SUMPRODUCT(W5:W24,$I$5:$I$24) | X31: =SUMPRODUCT(X5:X24,$I$5:$I$24)
